Workbook

Sheet Test Evaluation Result
A1: Pet Clinic Test Evaluation Result
A3: Summary of the results of test execution
A4: PETCLINIC | B4: PASSED | C4: FAILED | D4: Not Working
A5: Without comments | B5: =COUNTIFS(PetClinic!$D:$D,$A5,PetClinic!$I:$I,"PASS")&"/"&COUNTIF(PetClinic!$D:$D,$A5)&" ("&TEXT(COUNTIFS(PetClinic!$D:$D,$A5,PetClinic!$I:$I,"PASS")/COUNTIF(PetClinic!$D:$D,$A5),"0.0%")&")" -> 17/18 (94.4%) | C5: =COUNTIFS(PetClinic!$D:$D,$A5,PetClinic!$I:$I,"FAIL")&"/"&COUNTIF(PetClinic!$D:$D,$A5)&" ("&TEXT(COUNTIFS(PetClinic!$D:$D,$A5,PetClinic!$I:$I,"FAIL")/COUNTIF(PetClinic!$D:$D,$A5),"0.0%")&")" -> 1/18 (5.6%) | D5: =COUNTIFS(PetClinic!$D:$D,$A5,PetClinic!$I:$I,"<>FAIL",PetClinic!$I:$I,"<>PASS")&"/"&COUNTIF(PetClinic!$D:$D,$A5)&" ("&TEXT(COUNTIFS(PetClinic!$D:$D,$A5,PetClinic!$I:$I,"<>FAIL",PetClinic!$I:$I,"<>PASS")/COUNTIF(PetClinic!$D:$D,$A5),"0.0%")&")" -> 0/18 (0.0%)
A6: With comments | B6: =COUNTIFS(PetClinic!$D:$D,$A6,PetClinic!$I:$I,"PASS")&"/"&COUNTIF(PetClinic!$D:$D,$A6)&" ("&TEXT(COUNTIFS(PetClinic!$D:$D,$A6,PetClinic!$I:$I,"PASS")/COUNTIF(PetClinic!$D:$D,$A6),"0.0%")&")" -> 10/18 (55.6%) | C6: =COUNTIFS(PetClinic!$D:$D,$A6,PetClinic!$I:$I,"FAIL")&"/"&COUNTIF(PetClinic!$D:$D,$A6)&" ("&TEXT(COUNTIFS(PetClinic!$D:$D,$A6,PetClinic!$I:$I,"FAIL")/COUNTIF(PetClinic!$D:$D,$A6),"0.0%")&")" -> 1/18 (5.6%) | D6: =COUNTIFS(PetClinic!$D:$D,$A6,PetClinic!$I:$I,"<>FAIL",PetClinic!$I:$I,"<>PASS")&"/"&COUNTIF(PetClinic!$D:$D,$A6)&" ("&TEXT(COUNTIFS(PetClinic!$D:$D,$A6,PetClinic!$I:$I,"<>FAIL",PetClinic!$I:$I,"<>PASS")/COUNTIF(PetClinic!$D:$D,$A6),"0.0%")&")" -> 7/18 (38.9%)
A7: With comments plus web pages | B7: =COUNTIFS(PetClinic!$D:$D,$A7,PetClinic!$I:$I,"PASS")&"/"&COUNTIF(PetClinic!$D:$D,$A7)&" ("&TEXT(COUNTIFS(PetClinic!$D:$D,$A7,PetClinic!$I:$I,"PASS")/COUNTIF(PetClinic!$D:$D,$A7),"0.0%")&")" -> 17/18 (94.4%) | C7: =COUNTIFS(PetClinic!$D:$D,$A7,PetClinic!$I:$I,"FAIL")&"/"&COUNTIF(PetClinic!$D:$D,$A7)&" ("&TEXT(COUNTIFS(PetClinic!$D:$D,$A7,PetClinic!$I:$I,"FAIL")/COUNTIF(PetClinic!$D:$D,$A7),"0.0%")&")" -> 1/18 (5.6%) | D7: =COUNTIFS(PetClinic!$D:$D,$A7,PetClinic!$I:$I,"<>FAIL",PetClinic!$I:$I,"<>PASS")&"/"&COUNTIF(PetClinic!$D:$D,$A7)&" ("&TEXT(COUNTIFS(PetClinic!$D:$D,$A7,PetClinic!$I:$I,"<>FAIL",PetClinic!$I:$I,"<>PASS")/COUNTIF(PetClinic!$D:$D,$A7),"0.0%")&")" -> 0/18 (0.0%)
A9: Summary of the qualitative classification of each generated assertion
A10: PETCLINIC | B10: Correct | C10: Over-Assertive | D10: Under-Assertive | E10: Wrong | F10: Not Executable
A11: Without comments | B11: =COUNTIFS(PetClinic!$D:$D,$A11,PetClinic!$K:$K,"correct")&"/"&COUNTIF(PetClinic!$D:$D,$A11)&" ("&TEXT(COUNTIFS(PetClinic!$D:$D,$A11,PetClinic!$K:$K,"correct")/COUNTIF(PetClinic!$D:$D,$A11),"0.0%")&")" -> 0/18 (0.0%) | C11: =COUNTIFS(PetClinic!$D:$D,$A11,PetClinic!$K:$K,"over_assertive")&"/"&COUNTIF(PetClinic!$D:$D,$A11)&" ("&TEXT(COUNTIFS(PetClinic!$D:$D,$A11,PetClinic!$K:$K,"over_assertive")/COUNTIF(PetClinic!$D:$D,$A11),"0.0%")&")" -> 1/18 (5.6%) | D11: =COUNTIFS(PetClinic!$D:$D,$A11,PetClinic!$K:$K,"under_assertive")&"/"&COUNTIF(PetClinic!$D:$D,$A11)&" ("&TEXT(COUNTIFS(PetClinic!$D:$D,$A11,PetClinic!$K:$K,"under_assertive")/COUNTIF(PetClinic!$D:$D,$A11),"0.0%")&")" -> 5/18 (27.8%) | E11: =COUNTIFS(PetClinic!$D:$D,$A11,PetClinic!$K:$K,"wrong_assertion")&"/"&COUNTIF(PetClinic!$D:$D,$A11)&" ("&TEXT(COUNTIFS(PetClinic!$D:$D,$A11,PetClinic!$K:$K,"wrong_assertion")/COUNTIF(PetClinic!$D:$D,$A11),"0.0%")&")" -> 12/18 (66.7%) | F11: =COUNTIFS(PetClinic!$D:$D,$A11,PetClinic!$K:$K,"not_executable")&"/"&COUNTIF(PetClinic!$D:$D,$A11)&" ("&TEXT(COUNTIFS(PetClinic!$D:$D,$A11,PetClinic!$K:$K,"not_executable")/COUNTIF(PetClinic!$D:$D,$A11),"0.0%")&")" -> 0/18 (0.0%)
A12: With comments | B12: =COUNTIFS(PetClinic!$D:$D,$A12,PetClinic!$K:$K,"correct")&"/"&COUNTIF(PetClinic!$D:$D,$A12)&" ("&TEXT(COUNTIFS(PetClinic!$D:$D,$A12,PetClinic!$K:$K,"correct")/COUNTIF(PetClinic!$D:$D,$A12),"0.0%")&")" -> 5/18 (27.8%) | C12: =COUNTIFS(PetClinic!$D:$D,$A12,PetClinic!$K:$K,"over_assertive")&"/"&COUNTIF(PetClinic!$D:$D,$A12)&" ("&TEXT(COUNTIFS(PetClinic!$D:$D,$A12,PetClinic!$K:$K,"over_assertive")/COUNTIF(PetClinic!$D:$D,$A12),"0.0%")&")" -> 1/18 (5.6%) | D12: =COUNTIFS(PetClinic!$D:$D,$A12,PetClinic!$K:$K,"under_assertive")&"/"&COUNTIF(PetClinic!$D:$D,$A12)&" ("&TEXT(COUNTIFS(PetClinic!$D:$D,$A12,PetClinic!$K:$K,"under_assertive")/COUNTIF(PetClinic!$D:$D,$A12),"0.0%")&")" -> 3/18 (16.7%) | E12: =COUNTIFS(PetClinic!$D:$D,$A12,PetClinic!$K:$K,"wrong_assertion")&"/"&COUNTIF(PetClinic!$D:$D,$A12)&" ("&TEXT(COUNTIFS(PetClinic!$D:$D,$A12,PetClinic!$K:$K,"wrong_assertion")/COUNTIF(PetClinic!$D:$D,$A12),"0.0%")&")" -> 2/18 (11.1%) | F12: =COUNTIFS(PetClinic!$D:$D,$A12,PetClinic!$K:$K,"not_executable")&"/"&COUNTIF(PetClinic!$D:$D,$A12)&" ("&TEXT(COUNTIFS(PetClinic!$D:$D,$A12,PetClinic!$K:$K,"not_executable")/COUNTIF(PetClinic!$D:$D,$A12),"0.0%")&")" -> 7/18 (38.9%)
A13: With comments plus web pages | B13: =COUNTIFS(PetClinic!$D:$D,$A13,PetClinic!$K:$K,"correct")&"/"&COUNTIF(PetClinic!$D:$D,$A13)&" ("&TEXT(COUNTIFS(PetClinic!$D:$D,$A13,PetClinic!$K:$K,"correct")/COUNTIF(PetClinic!$D:$D,$A13),"0.0%")&")" -> 15/18 (83.3%) | C13: =COUNTIFS(PetClinic!$D:$D,$A13,PetClinic!$K:$K,"over_assertive")&"/"&COUNTIF(PetClinic!$D:$D,$A13)&" ("&TEXT(COUNTIFS(PetClinic!$D:$D,$A13,PetClinic!$K:$K,"over_assertive")/COUNTIF(PetClinic!$D:$D,$A13),"0.0%")&")" -> 2/18 (11.1%) | D13: =COUNTIFS(PetClinic!$D:$D,$A13,PetClinic!$K:$K,"under_assertive")&"/"&COUNTIF(PetClinic!$D:$D,$A13)&" ("&TEXT(COUNTIFS(PetClinic!$D:$D,$A13,PetClinic!$K:$K,"under_assertive")/COUNTIF(PetClinic!$D:$D,$A13),"0.0%")&")" -> 0/18 (0.0%) | E13: =COUNTIFS(PetClinic!$D:$D,$A13,PetClinic!$K:$K,"wrong_assertion")&"/"&COUNTIF(PetClinic!$D:$D,$A13)&" ("&TEXT(COUNTIFS(PetClinic!$D:$D,$A13,PetClinic!$K:$K,"wrong_assertion")/COUNTIF(PetClinic!$D:$D,$A13),"0.0%")&")" -> 0/18 (0.0%) | F13: =COUNTIFS(PetClinic!$D:$D,$A13,PetClinic!$K:$K,"not_executable")&"/"&COUNTIF(PetClinic!$D:$D,$A13)&" ("&TEXT(COUNTIFS(PetClinic!$D:$D,$A13,PetClinic!$K:$K,"not_executable")/COUNTIF(PetClinic!$D:$D,$A13),"0.0%")&")" -> 1/18 (5.6%)
A17: Kanboard Test Evaluation Result
A19: Summary of the results of test execution
A20: Kanboard | B20: PASSED | C20: FAILED | D20: Not Working
A21: Without comments | B21: =COUNTIFS(Kanboard!$D:$D,$A21,Kanboard!$I:$I,"PASS")&"/"&COUNTIF(Kanboard!$D:$D,$A21)&" ("&TEXT(COUNTIFS(Kanboard!$D:$D,$A21,Kanboard!$I:$I,"PASS")/COUNTIF(Kanboard!$D:$D,$A21),"0.0%")&")" -> 18/33 (54.5%) | C21: =COUNTIFS(Kanboard!$D:$D,$A21,Kanboard!$I:$I,"FAIL")&"/"&COUNTIF(Kanboard!$D:$D,$A21)&" ("&TEXT(COUNTIFS(Kanboard!$D:$D,$A21,Kanboard!$I:$I,"FAIL")/COUNTIF(Kanboard!$D:$D,$A21),"0.0%")&")" -> 11/33 (33.3%) | D21: =COUNTIFS(Kanboard!$D:$D,$A21,Kanboard!$I:$I,"<>FAIL",Kanboard!$I:$I,"<>PASS")&"/"&COUNTIF(Kanboard!$D:$D,$A21)&" ("&TEXT(COUNTIFS(Kanboard!$D:$D,$A21,Kanboard!$I:$I,"<>FAIL",Kanboard!$I:$I,"<>PASS")/COUNTIF(Kanboard!$D:$D,$A21),"0.0%")&")" -> 4/33 (12.1%)
A22: With comments | B22: =COUNTIFS(Kanboard!$D:$D,$A22,Kanboard!$I:$I,"PASS")&"/"&COUNTIF(Kanboard!$D:$D,$A22)&" ("&TEXT(COUNTIFS(Kanboard!$D:$D,$A22,Kanboard!$I:$I,"PASS")/COUNTIF(Kanboard!$D:$D,$A22),"0.0%")&")" -> 27/30 (90.0%) | C22: =COUNTIFS(Kanboard!$D:$D,$A22,Kanboard!$I:$I,"FAIL")&"/"&COUNTIF(Kanboard!$D:$D,$A22)&" ("&TEXT(COUNTIFS(Kanboard!$D:$D,$A22,Kanboard!$I:$I,"FAIL")/COUNTIF(Kanboard!$D:$D,$A22),"0.0%")&")" -> 2/30 (6.7%) | D22: =COUNTIFS(Kanboard!$D:$D,$A22,Kanboard!$I:$I,"<>FAIL",Kanboard!$I:$I,"<>PASS")&"/"&COUNTIF(Kanboard!$D:$D,$A22)&" ("&TEXT(COUNTIFS(Kanboard!$D:$D,$A22,Kanboard!$I:$I,"<>FAIL",Kanboard!$I:$I,"<>PASS")/COUNTIF(Kanboard!$D:$D,$A22),"0.0%")&")" -> 1/30 (3.3%)
A23: With comments and web pages | B23: =COUNTIFS(Kanboard!$D:$D,$A23,Kanboard!$I:$I,"PASS")&"/"&COUNTIF(Kanboard!$D:$D,$A23)&" ("&TEXT(COUNTIFS(Kanboard!$D:$D,$A23,Kanboard!$I:$I,"PASS")/COUNTIF(Kanboard!$D:$D,$A23),"0.0%")&")" -> 27/30 (90.0%) | C23: =COUNTIFS(Kanboard!$D:$D,$A23,Kanboard!$I:$I,"FAIL")&"/"&COUNTIF(Kanboard!$D:$D,$A23)&" ("&TEXT(COUNTIFS(Kanboard!$D:$D,$A23,Kanboard!$I:$I,"FAIL")/COUNTIF(Kanboard!$D:$D,$A23),"0.0%")&")" -> 2/30 (6.7%) | D23: =COUNTIFS(Kanboard!$D:$D,$A23,Kanboard!$I:$I,"<>FAIL",Kanboard!$I:$I,"<>PASS")&"/"&COUNTIF(Kanboard!$D:$D,$A23)&" ("&TEXT(COUNTIFS(Kanboard!$D:$D,$A23,Kanboard!$I:$I,"<>FAIL",Kanboard!$I:$I,"<>PASS")/COUNTIF(Kanboard!$D:$D,$A23),"0.0%")&")" -> 1/30 (3.3%)
A25: Summary of the qualitative classification of each generated assertion
A26: Kanboard | B26: Correct | C26: Over-Assertive | D26: Under-Assertive | E26: Wrong | F26: Not Executable
A27: Without comments | B27: =COUNTIFS(Kanboard!$D:$D,$A27,Kanboard!$K:$K,"correct")&"/"&COUNTIF(Kanboard!$D:$D,$A27)&" ("&TEXT(COUNTIFS(Kanboard!$D:$D,$A27,Kanboard!$K:$K,"correct")/COUNTIF(Kanboard!$D:$D,$A27),"0.0%")&")" -> 9/33 (27.3%) | C27: =COUNTIFS(Kanboard!$D:$D,$A27,Kanboard!$K:$K,"over_assertive")&"/"&COUNTIF(Kanboard!$D:$D,$A27)&" ("&TEXT(COUNTIFS(Kanboard!$D:$D,$A27,Kanboard!$K:$K,"over_assertive")/COUNTIF(Kanboard!$D:$D,$A27),"0.0%")&")" -> 3/33 (9.1%) | D27: =COUNTIFS(Kanboard!$D:$D,$A27,Kanboard!$K:$K,"under_assertive")&"/"&COUNTIF(Kanboard!$D:$D,$A27)&" ("&TEXT(COUNTIFS(Kanboard!$D:$D,$A27,Kanboard!$K:$K,"under_assertive")/COUNTIF(Kanboard!$D:$D,$A27),"0.0%")&")" -> 6/33 (18.2%) | E27: =COUNTIFS(Kanboard!$D:$D,$A27,Kanboard!$K:$K,"wrong_assertion")&"/"&COUNTIF(Kanboard!$D:$D,$A27)&" ("&TEXT(COUNTIFS(Kanboard!$D:$D,$A27,Kanboard!$K:$K,"wrong_assertion")/COUNTIF(Kanboard!$D:$D,$A27),"0.0%")&")" -> 12/33 (36.4%) | F27: =COUNTIFS(Kanboard!$D:$D,$A27,Kanboard!$K:$K,"not_executable")&"/"&COUNTIF(Kanboard!$D:$D,$A27)&" ("&TEXT(COUNTIFS(Kanboard!$D:$D,$A27,Kanboard!$K:$K,"not_executable")/COUNTIF(Kanboard!$D:$D,$A27),"0.0%")&")" -> 3/33 (9.1%)
A28: With comments | B28: =COUNTIFS(Kanboard!$D:$D,$A28,Kanboard!$K:$K,"correct")&"/"&COUNTIF(Kanboard!$D:$D,$A28)&" ("&TEXT(COUNTIFS(Kanboard!$D:$D,$A28,Kanboard!$K:$K,"correct")/COUNTIF(Kanboard!$D:$D,$A28),"0.0%")&")" -> 27/30 (90.0%) | C28: =COUNTIFS(Kanboard!$D:$D,$A28,Kanboard!$K:$K,"over_assertive")&"/"&COUNTIF(Kanboard!$D:$D,$A28)&" ("&TEXT(COUNTIFS(Kanboard!$D:$D,$A28,Kanboard!$K:$K,"over_assertive")/COUNTIF(Kanboard!$D:$D,$A28),"0.0%")&")" -> 0/30 (0.0%) | D28: =COUNTIFS(Kanboard!$D:$D,$A28,Kanboard!$K:$K,"under_assertive")&"/"&COUNTIF(Kanboard!$D:$D,$A28)&" ("&TEXT(COUNTIFS(Kanboard!$D:$D,$A28,Kanboard!$K:$K,"under_assertive")/COUNTIF(Kanboard!$D:$D,$A28),"0.0%")&")" -> 0/30 (0.0%) | E28: =COUNTIFS(Kanboard!$D:$D,$A28,Kanboard!$K:$K,"wrong_assertion")&"/"&COUNTIF(Kanboard!$D:$D,$A28)&" ("&TEXT(COUNTIFS(Kanboard!$D:$D,$A28,Kanboard!$K:$K,"wrong_assertion")/COUNTIF(Kanboard!$D:$D,$A28),"0.0%")&")" -> 3/30 (10.0%) | F28: =COUNTIFS(Kanboard!$D:$D,$A28,Kanboard!$K:$K,"not_executable")&"/"&COUNTIF(Kanboard!$D:$D,$A28)&" ("&TEXT(COUNTIFS(Kanboard!$D:$D,$A28,Kanboard!$K:$K,"not_executable")/COUNTIF(Kanboard!$D:$D,$A28),"0.0%")&")" -> 0/30 (0.0%)
A29: With comments and web pages | B29: =COUNTIFS(Kanboard!$D:$D,$A29,Kanboard!$K:$K,"correct")&"/"&COUNTIF(Kanboard!$D:$D,$A29)&" ("&TEXT(COUNTIFS(Kanboard!$D:$D,$A29,Kanboard!$K:$K,"correct")/COUNTIF(Kanboard!$D:$D,$A29),"0.0%")&")" -> 24/30 (80.0%) | C29: =COUNTIFS(Kanboard!$D:$D,$A29,Kanboard!$K:$K,"over_assertive")&"/"&COUNTIF(Kanboard!$D:$D,$A29)&" ("&TEXT(COUNTIFS(Kanboard!$D:$D,$A29,Kanboard!$K:$K,"over_assertive")/COUNTIF(Kanboard!$D:$D,$A29),"0.0%")&")" -> 1/30 (3.3%) | D29: =COUNTIFS(Kanboard!$D:$D,$A29,Kanboard!$K:$K,"under_assertive")&"/"&COUNTIF(Kanboard!$D:$D,$A29)&" ("&TEXT(COUNTIFS(Kanboard!$D:$D,$A29,Kanboard!$K:$K,"under_assertive")/COUNTIF(Kanboard!$D:$D,$A29),"0.0%")&")" -> 0/30 (0.0%) | E29: =COUNTIFS(Kanboard!$D:$D,$A29,Kanboard!$K:$K,"wrong_assertion")&"/"&COUNTIF(Kanboard!$D:$D,$A29)&" ("&TEXT(COUNTIFS(Kanboard!$D:$D,$A29,Kanboard!$K:$K,"wrong_assertion")/COUNTIF(Kanboard!$D:$D,$A29),"0.0%")&")" -> 5/30 (16.7%) | F29: =COUNTIFS(Kanboard!$D:$D,$A29,Kanboard!$K:$K,"not_executable")&"/"&COUNTIF(Kanboard!$D:$D,$A29)&" ("&TEXT(COUNTIFS(Kanboard!$D:$D,$A29,Kanboard!$K:$K,"not_executable")/COUNTIF(Kanboard!$D:$D,$A29),"0.0%")&")" -> 0/30 (0.0%)

Sheet PetClinic
A1: App | B1: Test Class | C1: Method | D1: Treatment | E1: Model | F1: Gold Standard Assertion | G1: Generated Assertion | H1: Compiles | I1: Pass/Fail | J1: Fail Reason | K1: Manual Classification | L1: Manual Notes
A2: PetClinic | B2: TestAddOwnerWithEmptyAddress | C2: TestAddOwnerWithEmptyAdressM | D2: Without comments | E2: Gemma 4-31B-IT | F2: assertEquals("must not be blank", driver.findElement(By.xpath("html[1]/body[1]/div[1]/div[1]/form[1]/div[1]/div[3]/div[1]/span[2]")) .getText()); | G2: org.junit.jupiter.api.Assertions.assertTrue(driver.findElement(By.cssSelector("[type='submit']")).isDisplayed()); | H2: TRUE | I2: PASS | K2: wrong_assertion | L2: Checks another objective: summit button visible instead of validation/error of the content.
A3: PetClinic | B3: TestAddOwnerWithEmptyAddress | C3: TestAddOwnerWithEmptyAdressM | D3: With comments | E3: Gemma 4-31B-IT | F3: assertEquals("must not be blank", driver.findElement(By.xpath("html[1]/body[1]/div[1]/div[1]/form[1]/div[1]/div[3]/div[1]/span[2]")) .getText()); | G3: assertEquals("must not be blank", driver.findElement(By.className("help-inline")).getText()); | H3: TRUE | I3: PASS | K3: under_assertive | L3: it would pass even if the anyother field is empty and Address field is filled
A4: PetClinic | B4: TestAddOwnerWithEmptyAddress | C4: TestAddOwnerWithEmptyAdressM | D4: With comments plus web pages | E4: Gemma 4-31B-IT | F4: assertEquals("must not be blank", driver.findElement(By.xpath("html[1]/body[1]/div[1]/div[1]/form[1]/div[1]/div[3]/div[1]/span[2]")) .getText()); | G4: assertEquals("must not be blank", driver.findElement(By.className("help-inline")).getText()); | H4: TRUE | I4: PASS | K4: correct | L4: Checks same expected validation text, locators differ
A5: PetClinic | B5: TestAddOwnerWithEmptyCity | C5: TestAddOwnerWithEmptyCityM | D5: Without comments | E5: Gemma 4-31B-IT | F5: assertEquals("must not be blank", driver.findElement(By.xpath("html[1]/body[1]/div[1]/div[1]/form[1]/div[1]/div[4]/div[1]/span[2]")) .getText()); | G5: org.junit.jupiter.api.Assertions.assertTrue(driver.findElement(By.cssSelector("[type='submit']")).isDisplayed()); | H5: TRUE | I5: PASS | K5: wrong_assertion | L5: Checks another objective: summit button visible instead of validation/error of the content.
A6: PetClinic | B6: TestAddOwnerWithEmptyCity | C6: TestAddOwnerWithEmptyCityM | D6: With comments | E6: Gemma 4-31B-IT | F6: assertEquals("must not be blank", driver.findElement(By.xpath("html[1]/body[1]/div[1]/div[1]/form[1]/div[1]/div[4]/div[1]/span[2]")) .getText()); | G6: assertEquals("must not be blank", driver.findElement(By.className("help-inline")).getText()); | H6: TRUE | I6: PASS | K6: under_assertive | L6: it would pass even if the anyother field is empty and City field is filled
A7: PetClinic | B7: TestAddOwnerWithEmptyCity | C7: TestAddOwnerWithEmptyCityM | D7: With comments plus web pages | E7: Gemma 4-31B-IT | F7: assertEquals("must not be blank", driver.findElement(By.xpath("html[1]/body[1]/div[1]/div[1]/form[1]/div[1]/div[4]/div[1]/span[2]")) .getText()); | G7: assertEquals("must not be blank", driver.findElement(By.className("help-inline")).getText()); | H7: TRUE | I7: PASS | K7: correct | L7: Same assertion intent and value, different selector.
A8: PetClinic | B8: TestAddOwnerWithEmptyFirstName | C8: TestAddOwnerWithEmptyFirstNameM | D8: Without comments | E8: Gemma 4-31B-IT | F8: assertEquals("must not be blank", driver.findElement(By.xpath("html[1]/body[1]/div[1]/div[1]/form[1]/div[1]/div[1]/div[1]/span[2]")) .getText()); | G8: org.junit.jupiter.api.Assertions.assertTrue(driver.findElement(By.cssSelector("[type='submit']")).isDisplayed()); | H8: TRUE | I8: PASS | K8: wrong_assertion | L8: Checks another objective: summit button visible instead of validation/error of the content.
A9: PetClinic | B9: TestAddOwnerWithEmptyFirstName | C9: TestAddOwnerWithEmptyFirstNameM | D9: With comments | E9: Gemma 4-31B-IT | F9: assertEquals("must not be blank", driver.findElement(By.xpath("html[1]/body[1]/div[1]/div[1]/form[1]/div[1]/div[1]/div[1]/span[2]")) .getText()); | G9: assertEquals("must not be blank", driver.findElement(By.xpath("//input[@id='firstName']/following-sibling::span[@class='help-inline']")).getText()); | H9: TRUE | I9: RUNTIME ERROR | J9: NoSuchElementException: no such element: Unable to locate element: {"method":"xpath","selector":"//input[@id='firstName']/following-sibling::span[@class='help-inline']"} | K9: not_executable | L9: Css selector not found
A10: PetClinic | B10: TestAddOwnerWithEmptyFirstName | C10: TestAddOwnerWithEmptyFirstNameM | D10: With comments plus web pages | E10: Gemma 4-31B-IT | F10: assertEquals("must not be blank", driver.findElement(By.xpath("html[1]/body[1]/div[1]/div[1]/form[1]/div[1]/div[1]/div[1]/span[2]")) .getText()); | G10: assertEquals("must not be blank", driver.findElement(By.className("help-inline")).getText()); | H10: TRUE | I10: PASS | K10: correct | L10: Equivalent first-name empty-field error checks.
A11: PetClinic | B11: TestAddOwnerWithEmptyLastName | C11: TestAddOwnerWithEmptyLastNameM | D11: Without comments | E11: Gemma 4-31B-IT | F11: assertEquals("must not be blank", driver.findElement(By.xpath("html[1]/body[1]/div[1]/div[1]/form[1]/div[1]/div[2]/div[1]/span[2]")) .getText()); | G11: org.junit.jupiter.api.Assertions.assertTrue(driver.findElement(By.cssSelector("[type='submit']")).isDisplayed()); | H11: TRUE | I11: PASS | K11: wrong_assertion | L11: Checks another objective: summit button visible instead of validation/error of the content.
A12: PetClinic | B12: TestAddOwnerWithEmptyLastName | C12: TestAddOwnerWithEmptyLastNameM | D12: With comments | E12: Gemma 4-31B-IT | F12: assertEquals("must not be blank", driver.findElement(By.xpath("html[1]/body[1]/div[1]/div[1]/form[1]/div[1]/div[2]/div[1]/span[2]")) .getText()); | G12: assertEquals("must not be blank", driver.findElement(By.xpath("//input[@id='lastName']/following-sibling::span[@class='help-inline']")).getText()); | H12: TRUE | I12: RUNTIME ERROR | J12: NoSuchElementException: no such element: Unable to locate element | K12: not_executable | L12: Css selector not found
A13: PetClinic | B13: TestAddOwnerWithEmptyLastName | C13: TestAddOwnerWithEmptyLastNameM | D13: With comments plus web pages | E13: Gemma 4-31B-IT | F13: assertEquals("must not be blank", driver.findElement(By.xpath("html[1]/body[1]/div[1]/div[1]/form[1]/div[1]/div[2]/div[1]/span[2]")) .getText()); | G13: assertEquals("must not be blank", driver.findElement(By.className("help-inline")).getText()); | H13: TRUE | I13: PASS | K13: correct | L13: Empty last-name empty-field error checks.
A14: PetClinic | B14: TestAddOwnerWithEmptyTelephone | C14: TestAddOwnerWithEmptyTelephoneM | D14: Without comments | E14: Gemma 4-31B-IT | F14: assertTrue( driver.findElement(By.xpath("html[1]/body[1]/div[1]/div[1]/form[1]/div[1]/div[5]/div[1]/span[2]")) .getText().contains("must not be blank")); | G14: org.junit.jupiter.api.Assertions.assertTrue(driver.findElement(By.cssSelector("[type='submit']")).isDisplayed()); | H14: TRUE | I14: PASS | K14: wrong_assertion | L14: Checks another objective: summit button visible instead of validation/error of the content.
A15: PetClinic | B15: TestAddOwnerWithEmptyTelephone | C15: TestAddOwnerWithEmptyTelephoneM | D15: With comments | E15: Gemma 4-31B-IT | F15: assertTrue( driver.findElement(By.xpath("html[1]/body[1]/div[1]/div[1]/form[1]/div[1]/div[5]/div[1]/span[2]")) .getText().contains("must not be blank")); | G15: assertTrue(driver.getPageSource().contains("must not be blank")); | H15: TRUE | I15: PASS | K15: wrong_assertion | L15: also checks other fields error messages so pass on even Telephone is filled
A16: PetClinic | B16: TestAddOwnerWithEmptyTelephone | C16: TestAddOwnerWithEmptyTelephoneM | D16: With comments plus web pages | E16: Gemma 4-31B-IT | F16: assertTrue( driver.findElement(By.xpath("html[1]/body[1]/div[1]/div[1]/form[1]/div[1]/div[5]/div[1]/span[2]")) .getText().contains("must not be blank")); | G16: assertTrue(driver.findElement(By.className("help-inline")).getText().contains("must not be blank")); | H16: TRUE | I16: PASS | K16: correct | L16: Same telephone empty-field message check using contains.
A17: PetClinic | B17: TestAddOwnerWithLongTelephone | C17: TestAddOwnerWithLongTelephoneM | D17: Without comments | E17: Gemma 4-31B-IT | F17: assertTrue( driver.findElement(By.xpath("html[1]/body[1]/div[1]/div[1]/form[1]/div[1]/div[5]/div[1]/span[2]")) .getText().contains("Telephone must be a 10-digit number")); | G17: org.junit.jupiter.api.Assertions.assertTrue(driver.findElement(By.cssSelector("[type='submit']")).isDisplayed()); | H17: TRUE | I17: PASS | K17: wrong_assertion | L17: Checks another objective: summit button visible instead of validation/error of the content.
A18: PetClinic | B18: TestAddOwnerWithLongTelephone | C18: TestAddOwnerWithLongTelephoneM | D18: With comments | E18: Gemma 4-31B-IT | F18: assertTrue( driver.findElement(By.xpath("html[1]/body[1]/div[1]/div[1]/form[1]/div[1]/div[5]/div[1]/span[2]")) .getText().contains("Telephone must be a 10-digit number")); | G18: assertTrue(driver.findElement(By.xpath("//*[contains(text(), 'Telephone must be a 10-digit number')]")).getText().contains("Telephone must be a 10-digit number")); | H18: TRUE | I18: PASS | K18: correct | L18: Its correct because we have only one field of Telephone number
A19: PetClinic | B19: TestAddOwnerWithLongTelephone | C19: TestAddOwnerWithLongTelephoneM | D19: With comments plus web pages | E19: Gemma 4-31B-IT | F19: assertTrue( driver.findElement(By.xpath("html[1]/body[1]/div[1]/div[1]/form[1]/div[1]/div[5]/div[1]/span[2]")) .getText().contains("Telephone must be a 10-digit number")); | G19: assertTrue(driver.findElement(By.className("help-inline")).getText().contains("Telephone must be a 10-digit number")); | H19: TRUE | I19: PASS | K19: correct | L19: Same telephone format error text check.
A20: PetClinic | B20: TestAddOwnerWithNotNumericTelephone | C20: TestAddOwnerWithNotNumericTelephoneM | D20: Without comments | E20: Gemma 4-31B-IT | F20: assertTrue( driver.findElement(By.xpath("html[1]/body[1]/div[1]/div[1]/form[1]/div[1]/div[5]/div[1]/span[2]")) .getText().contains("Telephone must be a 10-digit number")); | G20: org.junit.jupiter.api.Assertions.assertTrue(driver.findElement(By.cssSelector("[type='submit']")).isDisplayed()); | H20: TRUE | I20: PASS | K20: wrong_assertion | L20: Checks another objective: summit button visible instead of validation/error of the content.
A21: PetClinic | B21: TestAddOwnerWithNotNumericTelephone | C21: TestAddOwnerWithNotNumericTelephoneM | D21: With comments | E21: Gemma 4-31B-IT | F21: assertTrue( driver.findElement(By.xpath("html[1]/body[1]/div[1]/div[1]/form[1]/div[1]/div[5]/div[1]/span[2]")) .getText().contains("Telephone must be a 10-digit number")); | G21: assertTrue(driver.findElement(By.id("telephone.errors")).getText().contains("Telephone must be a 10-digit number")); | H21: TRUE | I21: RUNTIME ERROR | J21: NoSuchElementException: no such element: Unable to locate element: {"method":"css selector","selector":"#telephone\.errors"} | K21: not_executable | L21: unable to locate the ID because it doesn't exist
A22: PetClinic | B22: TestAddOwnerWithNotNumericTelephone | C22: TestAddOwnerWithNotNumericTelephoneM | D22: With comments plus web pages | E22: Gemma 4-31B-IT | F22: assertTrue( driver.findElement(By.xpath("html[1]/body[1]/div[1]/div[1]/form[1]/div[1]/div[5]/div[1]/span[2]")) .getText().contains("Telephone must be a 10-digit number")); | G22: assertTrue(driver.findElement(By.className("help-inline")).getText().contains("Telephone must be a 10-digit number")); | H22: TRUE | I22: PASS | K22: correct | L22: Same non-numeric telephone error message check.
A23: PetClinic | B23: TestAddOwnerWithValidData | C23: TestAddOwnerWithValidDataM | D23: Without comments | E23: Gemma 4-31B-IT | F23: assertEquals(firstName + " " + lastName, driver.findElement(By.xpath("html[1]/body[1]/div[1]/div[1]/table[1]/tbody[1]/tr[1]/td[1]/b[1]")) .getText(), "FirstName and LastName could not saved correctly"); | G23: org.junit.jupiter.api.Assertions.assertTrue(driver.getPageSource().contains(firstName + " " + lastName)); | H23: TRUE | I23: PASS | K23: under_assertive | L23: Same intent but weaker as it should check a specific target element/value
A24: PetClinic | B24: TestAddOwnerWithValidData | C24: TestAddOwnerWithValidDataM | D24: With comments | E24: Gemma 4-31B-IT | F24: assertEquals(firstName + " " + lastName, driver.findElement(By.xpath("html[1]/body[1]/div[1]/div[1]/table[1]/tbody[1]/tr[1]/td[1]/b[1]")) .getText(), "FirstName and LastName could not saved correctly"); | G24: assertEquals(firstName + " " + lastName, driver.findElement(By.xpath("//td[contains(text(), '" + firstName + "')]")).getText()); | H24: TRUE | I24: RUNTIME ERROR | J24: NoSuchElementException: no such element: Unable to locate element: {"method":"xpath","selector":"//td[contains(text(), 'Busra')]"} | K24: not_executable | L24: fails at the very first assertion due to nosuchelement
A25: PetClinic | B25: TestAddOwnerWithValidData | C25: TestAddOwnerWithValidDataM | D25: With comments plus web pages | E25: Gemma 4-31B-IT | F25: assertEquals(firstName + " " + lastName, driver.findElement(By.xpath("html[1]/body[1]/div[1]/div[1]/table[1]/tbody[1]/tr[1]/td[1]/b[1]")) .getText(), "FirstName and LastName could not saved correctly"); | G25: assertEquals(firstName + " " + lastName, driver.findElement(By.xpath("//th[text()='Name']/following-sibling::td")).getText()); | H25: TRUE | I25: PASS | K25: correct | L25: Same owner full-name equality check after save; alternate locator.
A26: PetClinic | B26: TestEditOwnerEmptyField | C26: TestEditOwnerEmptyFieldM | D26: Without comments | E26: Gemma 4-31B-IT | F26: assertEquals("must not be blank", driver.findElement(By.className("help-inline")).getText()); | G26: org.junit.jupiter.api.Assertions.assertTrue(driver.findElement(By.cssSelector("[type='submit']")).isDisplayed()); | H26: TRUE | I26: PASS | K26: wrong_assertion | L26: Checks another objective: summit button visible instead of validation/error of the content.
A27: PetClinic | B27: TestEditOwnerEmptyField | C27: TestEditOwnerEmptyFieldM | D27: With comments | E27: Gemma 4-31B-IT | F27: assertEquals("must not be blank", driver.findElement(By.className("help-inline")).getText()); | G27: assertEquals("must not be blank", driver.findElement(By.xpath("//span[contains(text(), 'must not be blank')]")).getText()); | H27: TRUE | I27: PASS | K27: correct | L27: Works fine even any fields is empty according to the class name, it's not specific to one field
A28: PetClinic | B28: TestEditOwnerEmptyField | C28: TestEditOwnerEmptyFieldM | D28: With comments plus web pages | E28: Gemma 4-31B-IT | F28: assertEquals("must not be blank", driver.findElement(By.className("help-inline")).getText()); | G28: assertEquals("must not be blank", driver.findElement(By.className("help-inline")).getText()); | H28: TRUE | I28: PASS | K28: correct | L28: Exact same assertion semantics as gold.
A29: PetClinic | B29: TestEditOwnerWithLongTelephone | C29: TestEditOwnerWithLongTelephoneM | D29: Without comments | E29: Gemma 4-31B-IT | F29: assertEquals("Telephone must be a 10-digit number", driver.findElement(By.className("help-inline")).getText()); | G29: org.junit.jupiter.api.Assertions.assertTrue(driver.findElement(By.cssSelector("[type='submit']")).isDisplayed()); | H29: TRUE | I29: PASS | K29: wrong_assertion | L29: Checks another objective: summit button visible instead of validation/error of the content.
A30: PetClinic | B30: TestEditOwnerWithLongTelephone | C30: TestEditOwnerWithLongTelephoneM | D30: With comments | E30: Gemma 4-31B-IT | F30: assertEquals("Telephone must be a 10-digit number", driver.findElement(By.className("help-inline")).getText()); | G30: assertEquals("Telephone must be a 10-digit number", driver.findElement(By.xpath("//*[contains(text(), 'Telephone must be a 10-digit number')]")).getText()); | H30: TRUE | I30: PASS | K30: correct | L30: Its correct because we have only one field of Telephone number which shows only this message
A31: PetClinic | B31: TestEditOwnerWithLongTelephone | C31: TestEditOwnerWithLongTelephoneM | D31: With comments plus web pages | E31: Gemma 4-31B-IT | F31: assertEquals("Telephone must be a 10-digit number", driver.findElement(By.className("help-inline")).getText()); | G31: assertEquals("Telephone must be a 10-digit number", driver.findElement(By.className("help-inline")).getText()); | H31: TRUE | I31: PASS | K31: correct | L31: Exact same assertion semantics as gold.
A32: PetClinic | B32: TestEditOwnerWithNotNumericTelephone | C32: TestEditOwnerWithNotNumericTelephoneM | D32: Without comments | E32: Gemma 4-31B-IT | F32: assertEquals("Telephone must be a 10-digit number", driver.findElement(By.className("help-inline")).getText()); | G32: org.junit.jupiter.api.Assertions.assertTrue(driver.findElement(By.cssSelector("[type='submit']")).isDisplayed()); | H32: TRUE | I32: PASS | K32: wrong_assertion | L32: Checks another objective: summit button visible instead of validation/error of the content.
A33: PetClinic | B33: TestEditOwnerWithNotNumericTelephone | C33: TestEditOwnerWithNotNumericTelephoneM | D33: With comments | E33: Gemma 4-31B-IT | F33: assertEquals("Telephone must be a 10-digit number", driver.findElement(By.className("help-inline")).getText()); | G33: assertEquals("Telephone must be a 10-digit number", driver.findElement(By.id("telephone.errors")).getText()); | H33: TRUE | I33: RUNTIME ERROR | J33: no such element: Unable to locate element: {"method":"css selector","selector":"#telephone\.errors"} | K33: not_executable | L33: telephone.errors ID not found in the structure
A34: PetClinic | B34: TestEditOwnerWithNotNumericTelephone | C34: TestEditOwnerWithNotNumericTelephoneM | D34: With comments plus web pages | E34: Gemma 4-31B-IT | F34: assertEquals("Telephone must be a 10-digit number", driver.findElement(By.className("help-inline")).getText()); | G34: assertEquals("Telephone must be a 10-digit number", driver.findElement(By.className("help-inline")).getText()); | H34: TRUE | I34: PASS | K34: correct | L34: Exact same assertion semantics as gold.
A35: PetClinic | B35: TestEditOwnerWithValidData | C35: TestEditOwnerWithValidDataM | D35: Without comments | E35: Gemma 4-31B-IT | F35: assertEquals(firstName + " " + lastName, driver.findElement(By.xpath("html[1]/body[1]/div[1]/div[1]/table[1]/tbody[1]/tr[1]/td[1]/b[1]")) .getText()); | G35: org.junit.jupiter.api.Assertions.assertTrue(driver.getPageSource().contains(firstName)); | H35: TRUE | I35: PASS | K35: under_assertive | L35: Same intent but weaker as it should check a specific target element/value
A36: PetClinic | B36: TestEditOwnerWithValidData | C36: TestEditOwnerWithValidDataM | D36: With comments | E36: Gemma 4-31B-IT | F36: assertEquals(firstName + " " + lastName, driver.findElement(By.xpath("html[1]/body[1]/div[1]/div[1]/table[1]/tbody[1]/tr[1]/td[1]/b[1]")) .getText()); | G36: assertEquals(firstName + " " + lastName, driver.findElement(By.xpath("//td[contains(text(), '" + firstName + "')]")).getText()); | H36: TRUE | I36: RUNTIME ERROR | J36: no such element: Unable to locate element: {"method":"xpath","selector":"//td[contains(text(), 'Bobo')]"} | K36: not_executable | L36: unable to locate the element
A37: PetClinic | B37: TestEditOwnerWithValidData | C37: TestEditOwnerWithValidDataM | D37: With comments plus web pages | E37: Gemma 4-31B-IT | F37: assertEquals(firstName + " " + lastName, driver.findElement(By.xpath("html[1]/body[1]/div[1]/div[1]/table[1]/tbody[1]/tr[1]/td[1]/b[1]")) .getText()); | G37: assertEquals(firstName + " " + lastName, driver.findElement(By.cssSelector("table.table-striped td b")).getText()); | H37: TRUE | I37: PASS | K37: correct | L37: Same edited owner full-name equality check; different locator style.
A38: PetClinic | B38: TestFindAllOwner | C38: TestFindAllOwnerM | D38: Without comments | E38: Gemma 4-31B-IT | F38: assertTrue(true); | G38: org.junit.jupiter.api.Assertions.assertTrue(driver.findElement(By.id("owners")).isDisplayed()); | H38: TRUE | I38: PASS | K38: over_assertive | L38: Gold assertion is tautological; generated adds UI constraint and is largely redundant with preceding findElement(By.id("owners"))
A39: PetClinic | B39: TestFindAllOwner | C39: TestFindAllOwnerM | D39: With comments | E39: Gemma 4-31B-IT | F39: assertTrue(true); | G39: assertTrue(driver.findElement(By.id("owners")).isDisplayed()); | H39: TRUE | I39: PASS | K39: over_assertive | L39: checking the UI element if it present
A40: PetClinic | B40: TestFindAllOwner | C40: TestFindAllOwnerM | D40: With comments plus web pages | E40: Gemma 4-31B-IT | F40: assertTrue(true); | G40: assertTrue(driver.findElement(By.id("owners")).isDisplayed()); | H40: TRUE | I40: PASS | K40: over_assertive | L40: Gold is trivial; generated adds stricter UI presence check.
...

Sheet Kanboard
A1: App | B1: Test Class | C1: Method | D1: Treatment | E1: Model | F1: Gold Standard Assertion | G1: Generated Assertion | H1: Compiles | I1: Pass/Fail | J1: Fail Reason | K1: Manual Classification | L1: Manual Notes
A2: Kanboard Baseline | B2: AddNewProject | C2: addNewProject | D2: Without comments | E2: Gemma 4-31B-IT | F2: assertEquals("Test 2", project.getTitle()); assertEquals("This project is open", project.getStatus()); | G2: assertEquals("Test 2", project.getTitle()); assertTrue(project.getTitle().contains("Test 2")); | H2: TRUE | I2: PASS | K2: wrong_assertion | L2: 2nd assertion re-checks title instead of status
A3: Kanboard Baseline | B3: AddNewProject | C3: addNewProject | D3: With comments | E3: Gemma 4-31B-IT | F3: assertEquals("Test 2", project.getTitle()); assertEquals("This project is open", project.getStatus()); | G3: assertEquals("Test 2", project.getTitle()); assertEquals("This project is open", project.getStatus()); | H3: TRUE | I3: PASS | K3: correct | L3: - the model was trying to verify the generated assertion with "mvn test" but I explictly state in the prompt not to run and verify it
A4: Kanboard Baseline | B4: AddNewProject | C4: addNewProject | D4: With comments and web pages | E4: Gemma 4-31B-IT | F4: assertEquals("Test 2", project.getTitle()); assertEquals("This project is open", project.getStatus()); | G4: assertEquals("Test 2", project.getTitle()); assertEquals("This project is open", project.getStatus()); | H4: TRUE | I4: PASS | K4: correct
A5: Kanboard Baseline | B5: AddEmptyProject | C5: addEmptyProject | D5: Without comments | E5: Gemma 4-31B-IT | F5: assertEquals("The project name is required", newProjPage.getErrorMessage()); | G5: assertFalse(newProjPage.getErrorMessage().isEmpty()); | H5: TRUE | I5: PASS | K5: under_assertive | L5: non-empty check, not specific message
A6: Kanboard Baseline | B6: AddEmptyProject | C6: addEmptyProject | D6: With comments | E6: Gemma 4-31B-IT | F6: assertEquals("The project name is required", newProjPage.getErrorMessage()); | G6: assertEquals("The project name is required", newProjPage.getErrorMessage()); | H6: TRUE | I6: PASS | K6: correct
A7: Kanboard Baseline | B7: AddEmptyProject | C7: addEmptyProject | D7: With comments and web pages | E7: Gemma 4-31B-IT | F7: assertEquals("The project name is required", newProjPage.getErrorMessage()); | G7: assertEquals("The project name is required", newProjPage.getErrorMessage()); | H7: TRUE | I7: PASS | K7: correct
A8: Kanboard Baseline | B8: AddNewTask | C8: addNewTask | D8: Without comments | E8: Gemma 4-31B-IT | F8: assertEquals("task 3", project.getFirstTaskName()); | G8: assertEquals("task 3", project.getFirstTaskName()); | H8: TRUE | I8: PASS | K8: correct
A9: Kanboard Baseline | B9: AddNewTask | C9: addNewTask | D9: With comments | E9: Gemma 4-31B-IT | F9: assertEquals("task 3", project.getFirstTaskName()); | G9: assertEquals("task 3", project.getFirstTaskName()); | H9: TRUE | I9: PASS | K9: correct
A10: Kanboard Baseline | B10: AddNewTask | C10: addNewTask | D10: With comments and web pages | E10: Gemma 4-31B-IT | F10: assertEquals("task 3", project.getFirstTaskName()); | G10: assertEquals("task 3", project.getFirstTaskName()); | H10: TRUE | I10: PASS | K10: correct
A11: Kanboard Baseline | B11: AddEmptyTask | C11: addEmptyTask | D11: Without comments | E11: Gemma 4-31B-IT | F11: assertEquals("The title is required", project.getErrorMessage()); | G11: assertEquals("Task title is required", project.getErrorMessage()); | H11: TRUE | I11: FAIL | J11: TestSuite.addEmptyTask expected: <Task title is required> but was: <The title is required> | K11: wrong_assertion | L11: Wrong expected value
A12: Kanboard Baseline | B12: AddEmptyTask | C12: addEmptyTask | D12: With comments | E12: Gemma 4-31B-IT | F12: assertEquals("The title is required", project.getErrorMessage()); | G12: assertEquals("The title is required", project.getErrorMessage()); | H12: TRUE | I12: PASS | K12: correct
A13: Kanboard Baseline | B13: AddEmptyTask | C13: addEmptyTask | D13: With comments and web pages | E13: Gemma 4-31B-IT | F13: assertEquals("The title is required", project.getErrorMessage()); | G13: assertEquals("The title is required", project.getErrorMessage()); | H13: TRUE | I13: PASS | K13: correct
A14: Kanboard Baseline | B14: EditProject | C14: editProduct | D14: Without comments | E14: Gemma 4-31B-IT | F14: assertEquals("This is the new description", project.getDescription()); | G14: assertEquals("This is the new description", project.getDescription()); | H14: TRUE | I14: PASS | K14: correct
A15: Kanboard Baseline | B15: EditProject | C15: editProduct | D15: With comments | E15: Gemma 4-31B-IT | F15: assertEquals("This is the new description", project.getDescription()); | G15: assertEquals("This is the new description", project.getDescription()); | H15: TRUE | I15: PASS | K15: correct
A16: Kanboard Baseline | B16: EditProject | C16: editProduct | D16: With comments and web pages | E16: Gemma 4-31B-IT | F16: assertEquals("This is the new description", project.getDescription()); | G16: assertEquals("This is the new description", project.getDescription()); | H16: TRUE | I16: PASS | K16: correct
A17: Kanboard Baseline | B17: AddNewColumn | C17: addNewColumn | D17: Without comments | E17: Gemma 4-31B-IT | F17: assertTrue(columns.getLastColumnName().contains("New Column 3")); | G17: assertEquals("New Column 3", columns.getLastColumnName()); | H17: TRUE | I17: FAIL | J17: TestSuite.addNewColumn expected: <New Column 3> but was: < New Column 3> | K17: over_assertive | L17: assertEquals stricter than assertTrue(contains)
A18: Kanboard Baseline | B18: AddNewColumn | C18: addNewColumn | D18: With comments | E18: Gemma 4-31B-IT | F18: assertTrue(columns.getLastColumnName().contains("New Column 3")); | G18: assertTrue(columns.getLastColumnName().equals("New Column 3")); | H18: TRUE | I18: FAIL | J18: ColumnsPage.getLastColumnName() uses a hard-coded XPath (tr[5]/td[1]) that targets the wrong row when the number of columns varies, so the test checks the wrong element/value and fails. | K18: wrong_assertion
A19: Kanboard Baseline | B19: AddNewColumn | C19: addNewColumn | D19: With comments and web pages | E19: Gemma 4-31B-IT | F19: assertTrue(columns.getLastColumnName().contains("New Column 3")); | G19: assertEquals("New Column 3", columns.getLastColumnName()); | H19: TRUE | I19: FAIL | J19: TestSuite.addNewColumn expected: <New Column 3> but was: < New Column 3> | K19: wrong_assertion
A20: Kanboard Baseline | B20: AddEmptyColumn | C20: addEmptyColumn | D20: Without comments | E20: Gemma 4-31B-IT | F20: assertEquals("The title is required", columns.getErrorMessage()); | G20: assertTrue(columns.isColumnPresent("")); | H20: FALSE | I20: COMPILATION ERROR | J20: cannot find symbol: method isColumnPresent(java.lang.String) | K20: not_executable | L20: After the first prompt, I told the LLM that the method did not exists. It generated the assertion below.
A21: Kanboard Baseline | B21: AddEmptyColumn | C21: addEmptyColumn | D21: Without comments | E21: Gemma 4-31B-IT | F21: assertEquals("The title is required", columns.getErrorMessage()); | G21: assertTrue(columns.getLastColumnName().isEmpty()); | H21: TRUE | I21: FAIL | J21: TestSuite.addEmptyColumn expected: <true> but was: <false> | K21: wrong_assertion | L21: checks column name, not error message
A22: Kanboard Baseline | B22: AddEmptyColumn | C22: addEmptyColumn | D22: With comments | E22: Gemma 4-31B-IT | F22: assertEquals("The title is required", columns.getErrorMessage()); | G22: assertEquals("The title is required", columns.getErrorMessage()); | H22: TRUE | I22: PASS | K22: correct
A23: Kanboard Baseline | B23: AddEmptyColumn | C23: addEmptyColumn | D23: With comments and web pages | E23: Gemma 4-31B-IT | F23: assertEquals("The title is required", columns.getErrorMessage()); | G23: assertEquals("The title is required", columns.getErrorMessage()); | H23: TRUE | I23: PASS | K23: correct
A24: Kanboard Baseline | B24: AddNewSwimlane | C24: addNewSwimlane | D24: Without comments | E24: Gemma 4-31B-IT | F24: assertTrue(swimlanes.getLastSwimlaneName().contains("New Swimlane 3")); | G24: assertEquals("New Swimlane 3", swimlanes.getLastSwimlaneName()); | H24: TRUE | I24: FAIL | J24: TestSuite.addNewSwimlane expected: <New Swimlane 3> but was: < New Swimlane 3> | K24: over_assertive | L24: assertEquals stricter than assertTrue(contains)
A25: Kanboard Baseline | B25: AddNewSwimlane | C25: addNewSwimlane | D25: With comments | E25: Gemma 4-31B-IT | F25: assertTrue(swimlanes.getLastSwimlaneName().contains("New Swimlane 3")); | G25: assertTrue(swimlanes.getLastSwimlaneName().equals("New Swimlane 3")); | H25: TRUE | I25: FAIL | J25: SwimlanesPage.getLastSwimlaneName() uses a hard-coded XPath tr[2]/td[1], which targets the wrong row when the table has a different number of swimlanes. So the test compares the wrong element/value. | K25: wrong_assertion
A26: Kanboard Baseline | B26: AddNewSwimlane | C26: addNewSwimlane | D26: With comments and web pages | E26: Gemma 4-31B-IT | F26: assertTrue(swimlanes.getLastSwimlaneName().contains("New Swimlane 3")); | G26: assertEquals("New Swimlane 3", swimlanes.getLastSwimlaneName()); | H26: TRUE | I26: FAIL | J26: TestSuite.addNewSwimlane expected: <New Swimlane 3> but was: < New Swimlane 3> | K26: wrong_assertion
A27: Kanboard Baseline | B27: AddEmptySwimlane | C27: addEmptySwimlane | D27: Without comments | E27: Gemma 4-31B-IT | F27: assertEquals("The name is required", swimlanes.getErrorMessage()); | G27: assertTrue(swimlanes.isSwimlanePresent("")); | H27: FALSE | I27: COMPILATION ERROR | J27: cannot find symbol: method isSwimlanePresent(java.lang.String) | K27: not_executable | L27: The name of the method is not appropriate as it does not reflect its intent. The LLM does not know the real intent.
A28: Kanboard Baseline | B28: AddEmptySwimlane | C28: addEmptySwimlane | D28: Without comments | E28: Gemma 4-31B-IT | F28: assertEquals("The name is required", swimlanes.getErrorMessage()); | G28: assertTrue(swimlanes.getLastSwimlaneName().isEmpty()); | H28: TRUE | I28: FAIL | J28: TestSuite.addNewSwimlane expected: <true> but was: <false> | K28: wrong_assertion | L28: check swimlane name, not error message
A29: Kanboard Baseline | B29: AddEmptySwimlane | C29: addEmptySwimlane | D29: With comments | E29: Gemma 4-31B-IT | F29: assertEquals("The name is required", swimlanes.getErrorMessage()); | G29: assertEquals("The name is required", swimlanes.getErrorMessage()); | H29: TRUE | I29: PASS | K29: correct
A30: Kanboard Baseline | B30: AddEmptySwimlane | C30: addEmptySwimlane | D30: With comments and web pages | E30: Gemma 4-31B-IT | F30: assertEquals("The name is required", swimlanes.getErrorMessage()); | G30: assertEquals("The name is required", swimlanes.getErrorMessage()); | H30: TRUE | I30: PASS | K30: correct
A31: Kanboard Baseline | B31: AddNewCategory | C31: addNewCategory | D31: Without comments | E31: Gemma 4-31B-IT | F31: assertTrue(categories.getCategoryName().contains("New Category 2")); | G31: assertTrue(categories.isCategoryPresent("New Category 2")); | H31: FALSE | I31: COMPILATION ERROR | J31: cannot find symbol: method isCategoryPresent(java.lang.String) | K31: not_executable
A32: Kanboard Baseline | B32: AddNewCategory | C32: addNewCategory | D32: Without comments | E32: Gemma 4-31B-IT | F32: assertTrue(categories.getCategoryName().contains("New Category 2")); | G32: Assertions.assertEquals("New Category 2", categories.getCategoryName()); | H32: TRUE | I32: PASS | K32: over_assertive | L32: assertEquals stricter than assertTrue(contains) | N32: Using the "no_coments_v2.txt" prompt from this moment
A33: Kanboard Baseline | B33: AddNewCategory | C33: addNewCategory | D33: With comments | E33: Gemma 4-31B-IT | F33: assertTrue(categories.getCategoryName().contains("New Category 2")); | G33: assertTrue(categories.getCategoryName().equals("New Category 2")); | H33: TRUE | I33: PASS | K33: correct
A34: Kanboard Baseline | B34: AddNewCategory | C34: addNewCategory | D34: With comments and web pages | E34: Gemma 4-31B-IT | F34: assertTrue(categories.getCategoryName().contains("New Category 2")); | G34: assertEquals("New Category 2", categories.getCategoryName()); | H34: TRUE | I34: PASS | K34: over_assertive | L34: assertEquals stricter than assertTrue(contains)
A35: Kanboard Baseline | B35: AddEmptyCategory | C35: addEmptyCategory | D35: Without comments | E35: Gemma 4-31B-IT | F35: assertEquals("The name is required", categories.getErrorMessage()); | G35: Assertions.assertTrue(categories.getErrorMessage().contains("Name is required")); | H35: TRUE | I35: FAIL | J35: TestSuite.addEmptyCategory expected: <true> but was: <false> | K35: wrong_assertion | L35: The LLM is aware that it doesn't know the actual error message so it tries to guess. During the thinking process it is hesitant on whether to check the length of the error messages.
A36: Kanboard Baseline | B36: AddEmptyCategory | C36: addEmptyCategory | D36: With comments | E36: Gemma 4-31B-IT | F36: assertEquals("The name is required", categories.getErrorMessage()); | G36: assertEquals("The name is required", categories.getErrorMessage()); | H36: TRUE | I36: PASS | K36: correct
A37: Kanboard Baseline | B37: AddEmptyCategory | C37: addEmptyCategory | D37: With comments and web pages | E37: Gemma 4-31B-IT | F37: assertEquals("The name is required", categories.getErrorMessage()); | G37: assertEquals("The name is required", categories.getErrorMessage()); | H37: TRUE | I37: PASS | K37: correct
A38: Kanboard Baseline | B38: EditProfile | C38: editProfile | D38: Without comments | E38: Gemma 4-31B-IT | F38: assertEquals("admin@kanboard.com", user.getEmail()); | G38: assertEquals("admin@kanboard.com", user.getEmail()); | H38: TRUE | I38: PASS | K38: correct | N38: Used the "no_coments_v2_1.txt" prompt from this moment
A39: Kanboard Baseline | B39: EditProfile | C39: editProfile | D39: With comments | E39: Gemma 4-31B-IT | F39: assertEquals("admin@kanboard.com", user.getEmail()); | G39: assertEquals("admin@kanboard.com", user.getEmail()); | H39: TRUE | I39: PASS | K39: correct
A40: Kanboard Baseline | B40: EditProfile | C40: editProfile | D40: With comments and web pages | E40: Gemma 4-31B-IT | F40: assertEquals("admin@kanboard.com", user.getEmail()); | G40: assertEquals("admin@kanboard.com", user.getEmail()); | H40: TRUE | I40: PASS | K40: correct | L40: Wrong page object, wrong variable, wrong field entirely; passes accidentally
...

Sheet Results
A1: App | B1: Test Class | C1: Method | D1: Treatment | E1: Model | F1: Gold Standard Assertion | G1: Generated Assertion | H1: Compiles | I1: Pass/Fail | J1: Fail Reason | K1: Manual Classification | L1: Manual Notes
A2: mantisbt | B2: AddCategoryTest | C2: addCategory | D2: Without comments | E2: Gemma-4-31B-it | F2: assertEquals(categoryName, editProj.getProjectCategory()); | G2: assertEquals(categoryName, editProj.getCategory()); | H2: TRUE | I2: RUN TIME ERROR | J2: no such element: Unable to locate element: {"method":"xpath","selector":"//*[@id="categories"]/div/div[3]/div/div/table/tbody/tr[1]/td[1]"} (Session info: chrome=127.0.6533.119) For documentation on this error, please visit: https://www.selenium.dev/documentation/webdriver/troubleshooting/errors#no-such-element-exception Build info: version: '4.35.0', revision: '1c58e5028b' System info: os.name: 'Mac OS X', os.arch: 'aarch64', os.version: '15.7.2', java.version: '17.0.17' Driver info: org.open | K2: wrong_assertion
A3: mantisbt | B3: AddEmptyUserFailsTest | C3: addEmptyUserFails | D3: With comments | E3: Gemma-4-31B-it | F3: assertEquals(Strings.errorInvalidUser, userPage.getError()); | G3: assertEquals(Strings.errorInvalidUser, userPage.getError()); | H3: TRUE | I3: PASSED | K3: correct
A4: mantisbt | B4: AddEmptyUserFailsTest | C4: addEmptyUserFails | D4: With comments plus web pages | E4: Gemma-4-31B-it | F4: assertEquals(Strings.errorInvalidUser, userPage.getError()); | G4: assertEquals(userPage.getError(), Strings.errorInvalidUser); | H4: TRUE | I4: PASSED | K4: correct
A5: mantisbt | B5: AddEmptyUserFailsTest | C5: addEmptyUserFails | D5: With comments plus web pages | E5: Gemma-4-31B-it | F5: assertEquals(Strings.errorInvalidUser, userPage.getError()); | G5: assertEquals(Strings.errorInvalidUser, userPage.getError()); | H5: TRUE | I5: PASSED | K5: correct
A6: mantisbt | B6: AddExistingCategoryFailsTest | C6: addExistingCategoryFails | D6: Without comments | E6: Gemma-4-31B-it | F6: assertEquals(Strings.existingCategoryError, editProj.getError()); | G6: assertTrue(editProj.getError().contains("Category already exists")); | H6: TRUE | I6: PASSED | K6: under_assertive
A7: mantisbt | B7: AddExistingCategoryFailsTest | C7: addExistingCategoryFails | D7: With comments | E7: Gemma-4-31B-it | F7: assertEquals(Strings.existingCategoryError, editProj.getError()); | G7: assertEquals(Strings.existingCategoryError, editProj.getError()); | H7: TRUE | I7: PASSED | K7: correct
A8: mantisbt | B8: AddExistingProjectFailsTest | C8: addExistingProjectFails | D8: Without comments | E8: Gemma-4-31B-it | F8: assertEquals(Strings.existingProjectError, project.getError()); | G8: assertEquals("Expected error message not displayed", "Project already exists", project.getError()); | H8: TRUE | I8: FAILED | J8: Expected error message not displayed expected:<[Project already exists]> but was:<[A project with that name already exists. Please go back and enter a different name.]> | K8: wrong_assertion

Sheet Classification Guide
A1: Classification | B1: When to use | C1: Example
A2: correct | B2: Generated checks the same thing as gold (same logic, maybe different syntax) | C2: Gold: assertEquals("updater", page.getAccessLevel(2)) Generated: assertTrue(page.getAccessLevel(2).equals("updater"))
A3: over_assertive | B3: Generated checks MORE than the gold (extra assertions or stricter checks) | C3: Gold: assertEquals("updater", page.getAccessLevel(2)) Generated: same + assertEquals("user001", page.getUsername(2))
A4: under_assertive | B4: Generated checks LESS than the gold (weaker, would pass when it should fail) | C4: Gold: assertEquals("updater", page.getAccessLevel(2)) Generated: assertTrue(driver.getPageSource().contains("updater"))
A5: wrong_assertion | B5: Generated checks the WRONG thing (different element, value, or logic) | C5: Gold: assertEquals("updater", page.getAccessLevel(2)) Generated: assertEquals("admin", page.getAccessLevel(1))
A6: not_executable | B6: Does not compile or cannot run | C6: Syntax error, missing method, wrong locator
